<?xml version="1.0" encoding="UTF-8"?>
<testng-results ignored="0" total="1" passed="0" failed="1" skipped="0">
  <reporter-output>
  </reporter-output>
  <suite started-at="2019-12-10T22:43:04Z" name="Default suite" finished-at="2019-12-10T22:43:18Z" duration-ms="14581">
    <groups>
    </groups>
    <test started-at="2019-12-10T22:43:04Z" name="Default test" finished-at="2019-12-10T22:43:18Z" duration-ms="14581">
      <class name="VerifyLogin.TC001_VerifyValidLogin">
        <test-method is-config="true" signature="intializeThis()[pri:0, instance:VerifyLogin.TC001_VerifyValidLogin@5e5d171f]" started-at="2019-12-10T14:43:04Z" name="intializeThis" finished-at="2019-12-10T14:43:06Z" duration-ms="2284" status="PASS">
          <reporter-output>
          </reporter-output>
        </test-method> <!-- intializeThis -->
        <test-method signature="validLogin()[pri:0, instance:VerifyLogin.TC001_VerifyValidLogin@5e5d171f]" started-at="2019-12-10T14:43:06Z" name="validLogin" finished-at="2019-12-10T14:43:13Z" duration-ms="7149" status="FAIL">
          <exception class="java.lang.AssertionError">
            <message>
              <![CDATA[expected [true] but found [false]]]>
            </message>
            <full-stacktrace>
              <![CDATA[java.lang.AssertionError: expected [true] but found [false]
	at org.testng.Assert.fail(Assert.java:94)
	at org.testng.Assert.failNotEquals(Assert.java:513)
	at org.testng.Assert.assertTrue(Assert.java:42)
	at org.testng.Assert.assertTrue(Assert.java:52)
	at VerifyLogin.TC001_VerifyValidLogin.validLogin(TC001_VerifyValidLogin.java:28)
	at java.base/jdk.internal.reflect.NativeMethodAccessorImpl.invoke0(Native Method)
	at java.base/jdk.internal.reflect.NativeMethodAccessorImpl.invoke(NativeMethodAccessorImpl.java:62)
	at java.base/jdk.internal.reflect.DelegatingMethodAccessorImpl.invoke(DelegatingMethodAccessorImpl.java:43)
	at java.base/java.lang.reflect.Method.invoke(Method.java:564)
	at org.testng.internal.MethodInvocationHelper.invokeMethod(MethodInvocationHelper.java:104)
	at org.testng.internal.Invoker.invokeMethod(Invoker.java:645)
	at org.testng.internal.Invoker.invokeTestMethod(Invoker.java:851)
	at org.testng.internal.Invoker.invokeTestMethods(Invoker.java:1177)
	at org.testng.internal.TestMethodWorker.invokeTestMethods(TestMethodWorker.java:129)
	at org.testng.internal.TestMethodWorker.run(TestMethodWorker.java:112)
	at org.testng.TestRunner.privateRun(TestRunner.java:756)
	at org.testng.TestRunner.run(TestRunner.java:610)
	at org.testng.SuiteRunner.runTest(SuiteRunner.java:387)
	at org.testng.SuiteRunner.runSequentially(SuiteRunner.java:382)
	at org.testng.SuiteRunner.privateRun(SuiteRunner.java:340)
	at org.testng.SuiteRunner.run(SuiteRunner.java:289)
	at org.testng.SuiteRunnerWorker.runSuite(SuiteRunnerWorker.java:52)
	at org.testng.SuiteRunnerWorker.run(SuiteRunnerWorker.java:86)
	at org.testng.TestNG.runSuitesSequentially(TestNG.java:1293)
	at org.testng.TestNG.runSuitesLocally(TestNG.java:1218)
	at org.testng.TestNG.runSuites(TestNG.java:1133)
	at org.testng.TestNG.run(TestNG.java:1104)
	at org.testng.remote.AbstractRemoteTestNG.run(AbstractRemoteTestNG.java:114)
	at org.testng.remote.RemoteTestNG.initAndRun(RemoteTestNG.java:251)
	at org.testng.remote.RemoteTestNG.main(RemoteTestNG.java:77)
]]>
            </full-stacktrace>
          </exception> <!-- java.lang.AssertionError -->
          <reporter-output>
          </reporter-output>
        </test-method> <!-- validLogin -->
        <test-method is-config="true" signature="closeBrowser()[pri:0, instance:VerifyLogin.TC001_VerifyValidLogin@5e5d171f]" started-at="2019-12-10T14:43:13Z" name="closeBrowser" finished-at="2019-12-10T14:43:18Z" duration-ms="5120" status="PASS">
          <reporter-output>
          </reporter-output>
        </test-method> <!-- closeBrowser -->
      </class> <!-- VerifyLogin.TC001_VerifyValidLogin -->
    </test> <!-- Default test -->
  </suite> <!-- Default suite -->
</testng-results>
